<!-- <?xml version="1.0" ?>
<!-- =================================================================================== -->
<!-- |    This document was autogenerated by xacro from urdf/robotrouge.urdf.xacro     | -->
<!-- |    EDITING THIS FILE BY HAND IS NOT RECOMMENDED                                 | -->
<!-- =================================================================================== -->
<robot name="robotrouge">
  <material name="arm_yellow">
    <color rgba="0.619607843137255 0.619607843137255 0.517647058823529 1" />
  </material>
  <material name="arm_gray">
    <color rgba="0.792156862745098 0.819607843137255 0.933333333333333 1" />
  </material>
  <!-- Init colour -->
  <material name="black">
    <color rgba="0.0 0.0 0.0 1.0" />
  </material>
  <material name="dark">
    <color rgba="0.3 0.3 0.3 1.0" />
  </material>
  <material name="light_black">
    <color rgba="0.4 0.4 0.4 1.0" />
  </material>
  <material name="blue">
    <color rgba="0.0 0.0 0.8 1.0" />
  </material>
  <material name="green">
    <color rgba="0.0 0.8 0.0 1.0" />
  </material>
  <material name="grey">
    <color rgba="0.5 0.5 0.5 1.0" />
  </material>
  <material name="orange">
    <color rgba="1.0 0.4235 0.0392 1.0" />
  </material>
  <material name="brown">
    <color rgba="0.8706 0.8118 0.7647 1.0" />
  </material>
  <material name="red">
    <color rgba="0.8 0.0 0.0 1.0" />
  </material>
  <material name="white">
    <color rgba="1.0 1.0 1.0 1.0" />
  </material>
  <link name="base_footprint" />
  <joint name="base_joint" type="fixed">
    <parent link="base_footprint" />
    <child link="base_link" />
    <origin rpy="0 0 0" xyz="0.0 0.0 0.0147" />
  </joint>
  <link name="base_link">
    <visual>
      <!-- <origin xyz="-0.032 0 0.0147" rpy="0 0 0"/> -->
      <origin rpy="0 0 3.14" xyz="0 0 -0.003" />
      <geometry>
        <!-- <box size="0.140 0.140 0.143"/> -->
        <mesh filename="package://jrb_description/meshes/base.STL" />
      </geometry>
      <material name="light_black" />
    </visual>
    <visual>
      <origin rpy="0 0 0" xyz="0 0 0" />
      <geometry>
        <mesh filename="package://jrb_description/meshes/carter.STL" />
      </geometry>
    </visual>
  </link>
  <joint name="laser_joint" type="fixed">
    <parent link="base_link" />
    <child link="laser_link" />
    <origin rpy="0 0 -1.5707963267948966" xyz="0.0 0.0 0.37733" />
  </joint>
  <link name="laser_link" />
  <joint name="wheel_left_joint" type="continuous">
    <parent link="base_link" />
    <child link="wheel_left_link" />
    <origin rpy="-1.57 0 0" xyz="0.0 0.08316 0.01004" />
    <axis xyz="0 0 1" />
  </joint>
  <link name="wheel_left_link">
    <visual>
      <origin rpy="1.57 0 0" xyz="0 0 0" />
      <geometry>
        <!-- <cylinder length="0.020" radius="0.0254"/> -->
        <mesh filename="package://jrb_description/meshes/roue.STL" />
      </geometry>
      <material name="dark" />
    </visual>
  </link>
  <joint name="wheel_right_joint" type="continuous">
    <parent link="base_link" />
    <child link="wheel_right_link" />
    <origin rpy="-1.57 0 0" xyz="0.0 -0.08316  0.01004" />
    <axis xyz="0 0 1" />
  </joint>
  <link name="wheel_right_link">
    <visual>
      <origin rpy="1.57 0 0" xyz="0 0 0" />
      <geometry>
        <!-- <cylinder length="0.018" radius="0.0254"/> -->
        <mesh filename="package://jrb_description/meshes/roue.STL" />
      </geometry>
      <material name="dark" />
    </visual>
    <inertial>
      <origin xyz="0 0 0" />
      <mass value="2.8498940e-02" />
      <inertia ixx="1.1175580e-05" ixy="-4.2369783e-11" ixz="-5.9381719e-09" iyy="1.1192413e-05" iyz="-1.4400107e-11" izz="2.0712558e-05" />
    </inertial>
  </link>
  <joint name="left_tag_joint" type="fixed">
    <parent link="base_link" />
    <child link="left_tag_link" />
    <origin rpy="0 0 0" xyz="0.091 0.0925 0.0" />
  </joint>
  <link name="left_tag_link">
    <visual>
      <origin rpy="0 0 0" xyz="0 0 0" />
      <geometry>
        <box size="0.02 0.02 0.001" />
      </geometry>
      <material name="dark" />
    </visual>
  </link>
  <joint name="right_tag_joint" type="fixed">
    <parent link="base_link" />
    <child link="right_tag_link" />
    <origin rpy="0 0 0" xyz="0.091 -0.0925 0.0" />
  </joint>
  <link name="right_tag_link">
    <visual>
      <origin rpy="0 0 0" xyz="0 0 0" />
      <geometry>
        <box size="0.02 0.02 0.001" />
      </geometry>
      <material name="dark" />
    </visual>
  </link>
  <joint name="th_camera_joint" type="fixed">
    <parent link="base_link" />
    <child link="th_camera_link" />
    <origin rpy="0 0 0" xyz="0.1468 0.0 0.317" />
  </joint>
  <link name="th_camera_link">
    <visual>
      <origin rpy="0 0 0" xyz="0 0 0" />
      <geometry>
        <box size="0.02 0.02 0.001" />
      </geometry>
      <material name="dark" />
    </visual>
  </link>
  <!-- Arms -->
  <link name="left_arm_origin_link" />
  <joint name="left_arm_origin_joint" type="fixed">
    <parent link="base_link" />
    <child link="left_arm_origin_link" />
    <origin rpy="0 0 -1.5707963267948966" xyz="0.0865 0.11275 0" />
  </joint>
  <link name="left_arm_base_link">
    <visual>
      <origin rpy="0 0 0" xyz="0 0 0" />
      <geometry>
        <mesh filename="package://jrb_description/meshes/left_arm_base_link.STL" />
      </geometry>
      <material name="arm_black">
        <color rgba="0.298039215686275 0.298039215686275 0.298039215686275 1" />
      </material>
    </visual>
  </link>
  <joint name="left_arm_joint" type="prismatic">
    <parent link="base_link" />
    <child link="left_arm_base_link" />
    <origin rpy="0 0 0" xyz="0.054 0.11275 0.029375" />
    <axis xyz="0 0 1" />
    <limit effort="30" lower="0.0" upper="0.224" velocity="1.0" />
  </joint>
  <link name="left_b">
    <visual>
      <origin rpy="0 0 0" xyz="0 0 0" />
      <geometry>
        <mesh filename="package://jrb_description/meshes/left_bras.STL" />
      </geometry>
      <material name="arm_yellow" />
    </visual>
  </link>
  <joint name="left_b_joint" type="revolute">
    <origin rpy="0 0 2.6179938779914944" xyz="0.02814995 0 0" />
    <parent link="left_arm_base_link" />
    <child link="left_b" />
    <axis xyz="0 0 -1" />
    <limit effort="30" lower="0.0" upper="5.235987755982989" velocity="1.0" />
  </joint>
  <link name="left_c">
    <visual>
      <origin rpy="0 0 0" xyz="0 0 0" />
      <geometry>
        <mesh filename="package://jrb_description/meshes/left_avant_bras.STL" />
      </geometry>
      <material name="arm_gray" />
    </visual>
  </link>
  <joint name="left_c_joint" type="revolute">
    <origin rpy="0 0 -2.6179938779914944" xyz="0.054 0 0" />
    <parent link="left_b" />
    <child link="left_c" />
    <axis xyz="0 0 1" />
    <limit effort="30" lower="0.0" upper="5.235987755982989" velocity="1.0" />
  </joint>
  <link name="left_d">
    <visual>
      <origin rpy="0 0 0" xyz="0 0 0" />
      <geometry>
        <mesh filename="package://jrb_description/meshes/poignet.STL" />
      </geometry>
      <material name="arm_gray" />
    </visual>
  </link>
  <joint name="left_d_joint" type="revolute">
    <origin rpy="0 -1.0471975511965976 0" xyz="0.031 0 -0.009" />
    <parent link="left_c" />
    <child link="left_d" />
    <axis xyz="0 1 0" />
    <limit effort="30" lower="0.0" upper="5.235987755982989" velocity="1.0" />
  </joint>
  <link name="left_e">
    <visual>
      <origin rpy="0 0 0" xyz="0 0 0" />
      <geometry>
        <mesh filename="package://jrb_description/meshes/left_prehenseur.STL" />
      </geometry>
      <material name="arm_yellow" />
    </visual>
  </link>
  <joint name="left_e_joint" type="revolute">
    <origin rpy="-4.1887902047863905 0 0" xyz="0.0319 0 0" />
    <parent link="left_d" />
    <child link="left_e" />
    <axis xyz="1 0 0" />
    <limit effort="30" lower="0.0" upper="5.235987755982989" velocity="1.0" />
  </joint>
  <link name="left_f">
    <visual>
      <origin rpy="0 0 0" xyz="0 0 0" />
      <geometry>
        <mesh filename="package://jrb_description/meshes/ventouse.STL" />
      </geometry>
      <material name="arm_gray" />
    </visual>
  </link>
  <joint name="left_f_joint" type="continuous">
    <origin rpy="0 0 0" xyz="0.02824 0 -0.029448" />
    <parent link="left_e" />
    <child link="left_f" />
    <axis xyz="0 0 1" />
  </joint>
  <link name="right_arm_origin_link" />
  <joint name="right_arm_origin_joint" type="fixed">
    <parent link="base_link" />
    <child link="right_arm_origin_link" />
    <origin rpy="0 0 -1.5707963267948966" xyz="0.0865 -0.11275 0" />
  </joint>
  <link name="right_arm_base_link">
    <visual>
      <origin rpy="0 0 0" xyz="0 0 0" />
      <geometry>
        <mesh filename="package://jrb_description/meshes/right_arm_base_link.STL" />
      </geometry>
      <material name="arm_black">
        <color rgba="0.298039215686275 0.298039215686275 0.298039215686275 1" />
      </material>
    </visual>
  </link>
  <joint name="right_arm_joint" type="prismatic">
    <parent link="base_link" />
    <child link="right_arm_base_link" />
    <origin rpy="0 0 0" xyz="0.054 -0.11275 0.029375" />
    <axis xyz="0 0 1" />
    <limit effort="30" lower="0.0" upper="0.224" velocity="1.0" />
  </joint>
  <link name="right_b">
    <visual>
      <origin rpy="0 0 0" xyz="0 0 0" />
      <geometry>
        <mesh filename="package://jrb_description/meshes/right_bras.STL" />
      </geometry>
      <material name="arm_yellow" />
    </visual>
  </link>
  <joint name="right_b_joint" type="revolute">
    <origin rpy="0 0 2.6179938779914944" xyz="0.02814995 0 0" />
    <parent link="right_arm_base_link" />
    <child link="right_b" />
    <axis xyz="0 0 -1" />
    <limit effort="30" lower="0.0" upper="5.235987755982989" velocity="1.0" />
  </joint>
  <link name="right_c">
    <visual>
      <origin rpy="0 0 0" xyz="0 0 0" />
      <geometry>
        <mesh filename="package://jrb_description/meshes/right_avant_bras.STL" />
      </geometry>
      <material name="arm_gray" />
    </visual>
  </link>
  <joint name="right_c_joint" type="revolute">
    <origin rpy="0 0 -2.6179938779914944" xyz="0.054 0 0" />
    <parent link="right_b" />
    <child link="right_c" />
    <axis xyz="0 0 1" />
    <limit effort="30" lower="0.0" upper="5.235987755982989" velocity="1.0" />
  </joint>
  <link name="right_d">
    <visual>
      <origin rpy="0 0 0" xyz="0 0 0" />
      <geometry>
        <mesh filename="package://jrb_description/meshes/poignet.STL" />
      </geometry>
      <material name="arm_gray" />
    </visual>
  </link>
  <joint name="right_d_joint" type="revolute">
    <origin rpy="0 -1.0471975511965976 0" xyz="0.031 0 -0.009" />
    <parent link="right_c" />
    <child link="right_d" />
    <axis xyz="0 1 0" />
    <limit effort="30" lower="0.0" upper="5.235987755982989" velocity="1.0" />
  </joint>
  <link name="right_e">
    <visual>
      <origin rpy="0 0 0" xyz="0 0 0" />
      <geometry>
        <mesh filename="package://jrb_description/meshes/right_prehenseur.STL" />
      </geometry>
      <material name="arm_yellow" />
    </visual>
  </link>
  <joint name="right_e_joint" type="revolute">
    <origin rpy="-4.1887902047863905 0 0" xyz="0.0319 0 0" />
    <parent link="right_d" />
    <child link="right_e" />
    <axis xyz="1 0 0" />
    <limit effort="30" lower="0.0" upper="5.235987755982989" velocity="1.0" />
  </joint>
  <link name="right_f">
    <visual>
      <origin rpy="0 0 0" xyz="0 0 0" />
      <geometry>
        <mesh filename="package://jrb_description/meshes/ventouse.STL" />
      </geometry>
      <material name="arm_gray" />
    </visual>
  </link>
  <joint name="right_f_joint" type="continuous">
    <origin rpy="0 0 0" xyz="0.02824 0 -0.029448" />
    <parent link="right_e" />
    <child link="right_f" />
    <axis xyz="0 0 1" />
  </joint>
</robot> -->