<?xml version="1.0" ?>
<robot name="robotrouge"
  xmlns:xacro="http://ros.org/wiki/xacro">

  <xacro:include filename="arm.urdf.xacro" />

  <!-- Init colour -->
  <material name="black">
      <color rgba="0.0 0.0 0.0 1.0"/>
  </material>

  <material name="dark">
    <color rgba="0.3 0.3 0.3 1.0"/>
  </material>

  <material name="light_black">
    <color rgba="0.4 0.4 0.4 1.0"/>
  </material>

  <material name="blue">
    <color rgba="0.0 0.0 0.8 1.0"/>
  </material>

  <material name="green">
    <color rgba="0.0 0.8 0.0 1.0"/>
  </material>

  <material name="grey">
    <color rgba="0.5 0.5 0.5 1.0"/>
  </material>

  <material name="orange">
    <color rgba="1.0 0.4235 0.0392 1.0"/>
  </material>

  <material name="brown">
    <color rgba="0.8706 0.8118 0.7647 1.0"/>
  </material>

  <material name="red">
    <color rgba="0.8 0.0 0.0 1.0"/>
  </material>

  <material name="white">
    <color rgba="1.0 1.0 1.0 1.0"/>
  </material>

  <link name="base_footprint"/>

  <joint name="base_joint" type="fixed">
    <parent link="base_footprint"/>
    <child link="base_link"/>
    <origin xyz="0.0 0.0 0.0147" rpy="0 0 0"/>
  </joint>

  <link name="base_link">
    <visual>
      <!-- <origin xyz="-0.032 0 0.0147" rpy="0 0 0"/> -->
      <origin xyz="0 0 -0.003" rpy="0 0 3.14"/>
      <geometry>
        <!-- <box size="0.140 0.140 0.143"/> -->
        <mesh filename="package://jrb_description/meshes/base.STL" />
      </geometry>
      <material name="light_black"/>
    </visual>

    <visual>
      <origin xyz="0 0 0" rpy="0 0 0"/>
      <geometry>
        <mesh filename="package://jrb_description/meshes/carter.STL" />
      </geometry>
    </visual>
  </link>

  <joint name="laser_join" type="fixed">
    <parent link="base_link" />
    <child link="laser_link" />
    <origin xyz="0.0 0.0 0.37733" rpy="0 0 0"/>
  </joint>

  <link name="laser_link" />

  <joint name="wheel_left_joint" type="continuous">
    <parent link="base_link"/>
    <child link="wheel_left_link"/>
    <origin xyz="0.0 0.08316 0.01004" rpy="-1.57 0 0"/>
    <axis xyz="0 0 1"/>
  </joint>

  <link name="wheel_left_link">
    <visual>
      <origin xyz="0 0 0" rpy="1.57 0 0"/>
      <geometry>
        <!-- <cylinder length="0.020" radius="0.0254"/> -->
        <mesh filename="package://jrb_description/meshes/roue.STL" />
      </geometry>
      <material name="dark"/>
    </visual>
  </link>

  <joint name="wheel_right_joint" type="continuous">
    <parent link="base_link"/>
    <child link="wheel_right_link"/>
    <origin xyz="0.0 -0.08316  0.01004" rpy="-1.57 0 0"/>
    <axis xyz="0 0 1"/>
  </joint>

  <link name="wheel_right_link">
    <visual>
      <origin xyz="0 0 0" rpy="1.57 0 0"/>
      <geometry>
        <!-- <cylinder length="0.018" radius="0.0254"/> -->
        <mesh filename="package://jrb_description/meshes/roue.STL" />
      </geometry>
      <material name="dark"/>
    </visual>

    <inertial>
      <origin xyz="0 0 0" />
      <mass value="2.8498940e-02" />
      <inertia ixx="1.1175580e-05" ixy="-4.2369783e-11" ixz="-5.9381719e-09" iyy="1.1192413e-05" iyz="-1.4400107e-11" izz="2.0712558e-05" />
    </inertial>
  </link>

  <joint name="left_tag_joint" type="fixed">
    <parent link="base_link"/>
    <child link="left_tag_link"/>
    <origin xyz="0.091 0.0925 0.0" rpy="0 0 0"/>
  </joint>

  <link name="left_tag_link">
    <visual>
      <origin xyz="0 0 0" rpy="0 0 0"/>
      <geometry>
        <box size="0.02 0.02 0.001"/>
      </geometry>
      <material name="dark"/>
    </visual>
  </link>

  <joint name="right_tag_joint" type="fixed">
    <parent link="base_link"/>
    <child link="right_tag_link"/>
    <origin xyz="0.091 -0.0925 0.0" rpy="0 0 0"/>
  </joint>

  <link name="right_tag_link">
    <visual>
      <origin xyz="0 0 0" rpy="0 0 0"/>
      <geometry>
        <box size="0.02 0.02 0.001"/>
      </geometry>
      <material name="dark"/>
    </visual>
  </link>

  <joint name="th_camera_joint" type="fixed">
    <parent link="base_link"/>
    <child link="th_camera_link"/>
    <origin xyz="0.1468 0.0 0.317" rpy="0 0 0"/>
  </joint>

  <link name="th_camera_link">
    <visual>
      <origin xyz="0 0 0" rpy="0 0 0"/>
      <geometry>
        <box size="0.02 0.02 0.001"/>
      </geometry>
      <material name="dark"/>
    </visual>
  </link>

  <!-- Arms -->

  <xacro:arm name="left" xyz="0.054 0.11275 0.029375" origin="0.0865 0.11275 0"/>
  <xacro:arm name="right" xyz="0.054 -0.11275 0.029375" origin="0.0865 -0.11275 0"/>
</robot>